Workbook
Name DUPLEX_CYBELES_CLARITA_WYNWOOD: CLIENTES!$A$15
Name DUPLEX_CYBELES_WYNWOOD: CLIENTES!$A$15
Name HENIA: CLIENTES!$A$55
Name HENIIA: CLIENTES!$A$24

Sheet CLIENTES
A1: CLIENTES | B1: DEUDA | C1: =SUMIF(B2:B61, "<0") -> -91227605
A2: TANTO | B2: ='POSADA DEL ANGEL'!G2 -> 0
A3: AOMA | B3: =AOMA!G2 -> -2940910
A4: BRISA DEL LAGO | B4: ='BRISA DEL LAGO'!G2 -> -366995
A5: BUENA VISTA | B5: ='BUENA VISTA'!G2 -> -505316
A6: CASEROS 248 | B6: ='GOLDEN ROSS'!G2 -> 0
A7: CATEDRAL | B7: =PARQUE!G2 -> -4349719
A8: CAUPLAS | B8: =LUCAS!G2 -> 0
A9: COLEGIO FARMACEUTICOS | B9: ='COLEGIO FARMACEUTICOS'!G2 -> -1498512
A10: COLONIA 12 DE OCTUBRE | B10: ='COLONIA 12 DE OCTUBRE'!G2 -> 0
A11: COLONIA 8 DE MARZO | B11: ='COLONIA 8 DE MARZO'!G2 -> -246804
A12: COMARCA | B12: =COMARCA!G2 -> 0
A13: CONDADO | B13: ='EL CONDADO'!G2 -> -4458176
A14: CONTINENTAL Y RUCA | B14: =CONTINENTAL!H2 -> 2695136
A15: CORONADO | B15: =CORONADO!G2 -> -1019581
A16: COSTA LAGO | B16: ='COSTA LAGO'!G2 -> -779358
A17: DOMUS AUDITORIUM | B17: ='DOMUS AUDITORIUM '!G1 -> -4735935
A18: HANS | B18: ='DOMUS CENTER'!G2 -> 0
A19: DOMUS LAKE | B19: ='LAKE DOMUS'!G2 -> 0
A20: DUPLEX - CYBELES - WYNWOOD | B20: =DUPLEX!G2 -> -1515709
A21: LUAR | B21: =EMBAJADOR!G2 -> 0
A22: ERNESTINA | B22: =ERNESTINA!G2 -> 0
A23: ESTILO | B23: =ESTILO!G2 -> 0
A24: GALA | B24: =GALA!G2 -> 101165
A25: HENIA | B25: =HENIA!G2 -> 0
A26: HOTEL 376 | B26: ='HOTEL 376'!G2 -> -2769039
A27: IMPERIAL | B27: =IMPERIAL!G2 -> -64227
A28: INTERLAC | B28: =INTERLAC!G2 -> -5189294
A29: INTI HUASI-NEVADO-LAGO AZUL-CONDOR | B29: ='INTI HUASI'!G2 -> -35059823
A30: LE MIRAGE | B30: ='LE MIRAGE'!G2 -> -2950168
A31: MADERO | B31: =MADERO!G2 -> 0
A32: COLONIA DE TANTI (FATLYF) | B32: =MARBOT!G2 -> 0
A33: MIRADOR DE LA VILLA | B33: ='MIRADOR DE LA VILLA'!G2 -> 909967
A34: MIRADOR DE LAS SIERRAS | B34: ='MIRADOR DE LAS SIERRAS'!G2 -> 0
A35: MORADILLO | B35: =MORADILLO!G2 -> 0
A36: NAZARETH | B36: =NAZARETH!G2 -> 0
A37: PANORAMA | B37: =PANORAMA!G2 -> 0
A38: PINARES CERRO HOTEL | B38: ='PINARES CERRO HOTEL'!G2 -> 0
A39: PINARES CERRO MANTELERIA | B39: ='PINARES CERRO MANTELERIA'!G2 -> 0
A40: PINARES PANORAMA HOTEL | B40: ='PINARES PANORAMA HOTEL'!G2 -> 0
...

Sheet AOMA
A1: AOMA | D1: volver
A2: FECHA | B2: IMPORTE ADEUDADO | C2: ENTREGAS | D2: FORMA DE PAGO | E2: DETALLE | F2: TOTAL | G2: =SUM(C3:C1048576) - SUM(B3:B1048576) -> -2940910
A3: 45443 | B3: 144522
A5: 45473 | B5: 222104
A6: 45493 | C6: 252547 | D6: CHEQUE | E6: 225514 FECHA 25/8
A7: 45504 | B7: 702967
A8: 45530 | C8: 702567
A9: 45535 | B9: 431826
A10: 45565 | B10: 62841
A11: 45583 | C11: 541070 | D11: 2 cheq
A12: 45596 | B12: 370781
B13: 6638
A14: 45601 | C14: 445495
A15: 45626 | B15: 756622
A16: 45657 | B16: 189735
A17: 45665 | C17: 797447 | D17: 2 CHEQ
A18: 45688 | B18: 1179871
A19: 45692 | C19: 410690 | D19: CHEQUE
A20: 45692 | C20: 500000 | D20: CHEQUE
A21: 45716 | B21: 988379
A22: 45747 | B22: 320135
A23: 45763 | C23: 1257388 | D23: CHEQUE
A24: 45777 | B24: 865826
A25: 45794 | C25: 453680 | D25: CHEQUE
A26: 45807 | B26: 429957
A27: 45838 | B27: 204721
A28: 45862 | C28: 500000 | D28: CHEQUE
A29: 45869 | B29: 312373
A30: 45900 | B30: 346855
A31: 45930 | B31: 557784
A32: 45931 | C32: 675269 | D32: CHEQUES
A33: 45961 | B33: 493328
A34: 45964 | C34: 500000 | D34: CHEQUE
A35: 45981 | C35: 500000 | D35: CHEQUE
A36: 45991 | B36: 531936
A37: 45997 | C37: 400000 | D37: CHEQUE
A38: 46021 | C38: 1703454 | D38: cheques
A39: 46022 | B39: 647394
A40: 46053 | C40: 474200
A41: 46053 | B41: 1640923
...

Sheet DOMUS CENTER
A1: HANS | D1: volver | F1: TOTAL | G1: =SUM(C2:C1048576) - SUM(B2:B1048576) -> 0
A2: FECHA | B2: IMPORTE ADEUDADO | C2: ENTREGAS | D2: FORMA DE PAGO | E2: DETALLE | F2: TOTAL | G2: =SUM(C3:C1048576) - SUM(B3:B1048576) -> 0
A3: 46053 | B3: 58200
A4: 46053 | C4: 58200

Sheet DOMUS AUDITORIUM 
A1: DOMUS AUDITORIUM | D1: volver | F1: TOTAL | G1: =SUM(C2:C1048576) - SUM(B2:B1048576) -> -4735935
A2: FECHA | B2: IMPORTE ADEUDADO | C2: ENTREGAS | D2: FORMA DE PAGO | E2: DETALLE | F2: TOTAL | G2: =SUM(C3:C1048576) - SUM(B3:B1048576) -> -4735935
A3: 45322 | B3: 953286 | E3: AJUSTE
A4: 45351 | C4: 263500 | D4: 792984 CHEQUE
A5: 45351 | C5: 689800 | D5: EFECTIVO
A6: 45351 | B6: 1628134 | E6: CENTER
A7: 45351 | B7: 2448743 | E7: AUDITORIUM
A8: 45357 | C8: 969800 | D8: CHEQ
A9: 45379 | C9: 1540000 | D9: CHEQUES
A10: 45384 | B10: 1848289 | E10: AUDITORIUM
A11: 45384 | B11: 1394300 | E11: CENTER
A12: 45404 | C12: 2000000 | D12: CHEQUES
A13: 45421 | B13: 1729206 | E13: CENTER
A14: 45421 | B14: 1994837 | E14: AUDITORIUM
A15: 45441 | C15: 7500000 | D15: CHEQUES 5 1.5
A16: 45444 | B16: 1429525 | E16: CENTER
A17: 45444 | B17: 1496255 | E17: AUDITORIUM
A18: 45469 | C18: 453000 | D18: CHEQUE
A19: 45474 | B19: 995140 | E19: AUDITORIUM
A20: 45474 | B20: 1256099 | E20: CENTER
A21: 45491 | C21: 1000000 | D21: EFECTIVO
A22: 45498 | C22: 940000 | D22: cheq 478649
A23: 45504 | B23: 2906564 | E23: AUDITORIUM
A24: 45504 | B24: 2051926 | E24: CENTER
A25: 45504 | C25: 1370000 | D25: TRANSF
A26: 45525 | C26: 300000 | D26: cheq
A27: 45530 | C27: 2008000 | D27: efect. Y transf
A28: 45535 | B28: 1540111 | E28: AUDITORIUM
A29: 45535 | B29: 2094228 | E29: CENTER
A30: 45540 | C30: 1310000 | D30: CHEQ
A31: 45555 | C31: 1500000 | D31: EFECT
A32: 45554 | C32: 1000000 | D32: EFECT
A33: 45565 | B33: 3032317 | E33: AUDITORIUM
A34: 45565 | B34: 2131406 | E34: CENTER
A35: 45567 | C35: 1000000 | D35: EFECT
A36: 45567 | C36: 60750 | D36: CUBRE CAMA
A37: 45572 | C37: 1790980 | D37: TRANSF. VARIAS.
A38: 45581 | C38: 964968 | D38: TRANSF A MI
A39: 45594 | C39: 2255750 | D39: TRANSF. VARIAS.
A40: 45596 | B40: 2138730 | E40: CENTER
...

Sheet BRISA DEL LAGO
A1: BRISA DEL LAGO | D1: volver
A2: FECHA | B2: IMPORTE ADEUDADO | C2: ENTREGAS | D2: FORMA DE PAGO | E2: DETALLE | F2: TOTAL | G2: =SUM(C3:C1048576) - SUM(B3:B1048576) -> -366995
A3: 45443 | B3: 18723
A4: 45473 | B4: 40297
A5: 45493 | C5: 59020
A6: 45504 | B6: 268388
A7: 45526 | C7: 200000
A8: 45535 | B8: 57693
A9: 45565 | B9: 100316
A10: 45593 | C10: 115000
A11: 45596 | B11: 80004
A12: 45604 | C12: 111397
A13: 45616 | B13: 74041
A14: 45633 | C14: 74041
A15: 45657 | B15: 137021
A16: 45665 | C16: 137021
A17: 45680 | C17: 80004
A18: 45688 | B18: 377001
A19: 45707 | C19: 360000
A20: 45716 | B20: 285774
A21: 45726 | C21: 302775
A22: 45747 | B22: 195681
A23: 45777 | C23: 195681
A24: 45777 | B24: 31210
A25: 45807 | B25: 104178
A26: 45831 | C26: 135388
A27: 45900 | B27: 149618
A28: 45901 | C28: 149618
A29: 45930 | B29: 109548
A30: 45953 | C30: 109548
A31: 45961 | B31: 122062
A32: 45991 | B32: 120570
A33: 46022 | B33: 247662
A34: 46034 | C34: 242632
A35: 46053 | B35: 496518
A36: 46062 | C36: 247662
A37: 46073 | C37: 456500
A38: 46081 | B38: 326977

Sheet BUENA VISTA
A1: BUENA VISTA | D1: volver
A2: FECHA | B2: IMPORTE ADEUDADO | C2: ENTREGAS | D2: FORMA DE PAGO | E2: DETALLE | F2: TOTAL | G2: =SUM(C4:C1048576) - SUM(B4:B1048576) -> -505316
A4: 45443 | B4: 152992
A5: 45473 | B5: 54988
A6: 45483 | C6: 153000
A7: 45504 | B7: 155341
A8: 45535 | B8: 34479
A9: 45565 | B9: 97424
A10: 45596 | B10: 102603
A11: 45626 | B11: 265837
A12: 45657 | B12: 192328
A13: 45671 | C13: 902992
A14: 45688 | B14: 737405
A15: 45716 | B15: 487949
A16: 45747 | B16: 224436
A17: 45756 | C17: 1076000
A18: 45777 | B18: 141993
A19: 45789 | C19: 464000
A20: 45807 | B20: 101057
A21: 45859 | C21: 150000
A22: 45869 | B22: 390407
A23: 45900 | B23: 124090
A24: 45909 | C24: 517337
A25: 45930 | B25: 216848
A26: 45961 | B26: 131977
A27: 45982 | C27: 131977
A28: 45991 | B28: 138138
A29: 46022 | C29: 350000
A30: 46022 | B30: 155666
A31: 46034 | C31: 160652
A32: 46053 | B32: 938170
A33: 46053 | C33: 253500 | D33: toallones descuento
A34: 46062 | C34: 684670
A35: 46081 | B35: 505316

Sheet CAPVIO
A1: EL CID | D1: volver
A2: FECHA | B2: IMPORTE ADEUDADO | C2: ENTREGAS | D2: FORMA DE PAGO | E2: DETALLE | F2: TOTAL | G2: =SUM(C3:C1048576) - SUM(B3:B1048576) -> -374343
A3: 46092 | B3: 374343

Sheet CIERVO DE ORO
A1: CIERVO DE ORO | D1: volver
A2: FECHA | B2: IMPORTE ADEUDADO | C2: ENTREGAS | D2: FORMA DE PAGO | E2: DETALLE | F2: TOTAL | G2: =SUM(C3:C1048576) - SUM(B3:B1048576) -> -1254582
A3: 45443 | B3: 771057
A4: 45473 | B4: 483525

Sheet CLARITA
A1: CLARITA | D1: volver
A2: FECHA | B2: IMPORTE ADEUDADO | C2: ENTREGAS | D2: FORMA DE PAGO | E2: DETALLE | F2: TOTAL | G2: =SUM(C3:C1048576) - SUM(B3:B1048576) -> -418042
A3: 45443 | B3: 41034 | E3: CLARITA
A4: 45473 | B4: 130458 | E4: CLARITA
A5: 45504 | B5: 246550 | E5: CLARITA

Sheet COLEGIO FARMACEUTICOS
A1: COLEGIO FARMACEUTICOS | D1: volver
A2: FECHA | B2: IMPORTE ADEUDADO | C2: ENTREGAS | D2: FORMA DE PAGO | E2: DETALLE | F2: TOTAL | G2: =SUM(C4:C1048576) - SUM(B4:B1048576) -> -1498512
A4: 45443 | B4: 353553
A5: 45459 | C5: 353553
A6: 45473 | B6: 266851
A7: 45491 | C7: 266851
A8: 45504 | B8: 489524
A9: 45519 | C9: 489524
A10: 45535 | B10: 161566
A11: 45565 | B11: 577102
A12: 45596 | B12: 563158
A13: 45603 | C13: 555193
A14: 45626 | B14: 486191
A15: 45657 | B15: 687649
A16: 45674 | C16: 486191
A17: 45688 | B17: 1234118
A18: 45701 | C18: 1921767
A19: 45716 | B19: 1152564
A20: 45729 | C20: 1152564
A21: 45747 | B21: 694757
A22: 45763 | C22: 1441390
A23: 45777 | B23: 632144
A24: 45792 | C24: 632144
A25: 45807 | B25: 585244
A26: 45813 | C26: 585244
A27: 45838 | B27: 540636
A28: 45841 | C28: 540636
A29: 45869 | B29: 574405
A30: 45876 | C30: 574405
A31: 45900 | B31: 626373
A32: 45904 | C32: 626373
A33: 45930 | B33: 698988
A34: 45961 | B34: 828063
A35: 45966 | C35: 1527051
A36: 45991 | B36: 848234
A37: 46022 | B37: 1375882
A38: 46034 | C38: 848234
A39: 46037 | C39: 1375882
A40: 46053 | B40: 1762514
A41: 46081 | B41: 1498512
...

Sheet COLONIA 12 DE OCTUBRE
A1: COLONIA 12 DE OCTUBRE | D1: volver
A2: FECHA | B2: IMPORTE ADEUDADO | C2: ENTREGAS | D2: FORMA DE PAGO | E2: DETALLE | F2: TOTAL | G2: =SUM(C3:C1048576) - SUM(B3:B1048576) -> 0
A4: 45473
A5: 45504 | B5: 428112
A6: 45512 | C6: 428112
A7: 45535 | B7: 0
A8: 45565 | B8: 601024
A9: 45581 | C9: 601024
A10: 45596 | B10: 444015
A11: 45602 | C11: 444015
A12: 45626 | B12: 259270
A13: 45639 | C13: 168310
A14: 45649 | C14: 90960
A15: 45657 | B15: 653788
A16: 45663 | C16: 653788
A17: 45679 | B17: 1373986
A18: 45688 | C18: 1373986
A19: 45688 | B19: 1847588
A20: 45700 | C20: 1847588
A21: 45716 | B21: 1541380
A22: 45741 | C22: 1541380
A23: 45742 | B23: 608186
A24: 45745 | C24: 608186
A25: 45747 | B25: 852590
A26: 45750 | C26: 852590
A27: 45777 | B27: 954301
A28: 45786 | C28: 954301
A29: 45807 | B29: 106646
A30: 45838 | B30: 63782
A31: 45873 | C31: 170428
A32: 46038 | B32: 1472264
A33: 46052 | C33: 1472264
A34: 46053 | B34: 1413701
A35: 46059 | C35: 1413701
A36: 46068 | B36: 1736918
A37: 46073 | C37: 1736918
A38: 46069 | B38: 1339359
A39: 46085 | C39: 1339359

Sheet COMARCA
A1: COMARCA | D1: volver
A2: FECHA | B2: IMPORTE ADEUDADO | C2: ENTREGAS | D2: FORMA DE PAGO | E2: DETALLE | F2: TOTAL | G2: =SUM(C4:C1048576) - SUM(B4:B1048576) -> 0
A4: 45443 | B4: 81097
A5: 45473 | B5: 164923
A6: 45504 | B6: 277432
A7: 45533 | C7: 523452
A8: 45535 | B8: 108703
A9: 45565 | B9: 196345
A10: 45596 | B10: 218409
A11: 45626 | B11: 399432
A12: 45639 | C12: 922889
A13: 45657 | B13: 370549
A14: 45688 | B14: 1133051
A15: 45716 | B15: 707458
A16: 45726 | C16: 2211058
A17: 45747 | B17: 296211
A18: 45807 | B18: 158946
A19: 45838 | B19: 197108
A20: 45869 | B20: 222948
A21: 45900 | B21: 176628
A22: 45930 | B22: 191454
A23: 45961 | B23: 286518
A24: 45991 | C24: 1500000
A25: 45991 | B25: 422246
A26: 46022 | B26: 399616
A27: 46053 | B27: 1289185
A28: 46081 | B28: 966786
A29: 46084 | C29: 3107646

Sheet CONDOR
A1: CONDOR | D1: volver
A2: FECHA | B2: IMPORTE ADEUDADO | C2: ENTREGAS | D2: FORMA DE PAGO | E2: DETALLE | F2: TOTAL | G2: =SUM(C3:C1048576) - SUM(B3:B1048576) -> 0

Sheet COLONIA 8 DE MARZO
A1: COLONIA 8 DE MARZO | D1: volver
A2: FECHA | B2: IMPORTE ADEUDADO | C2: ENTREGAS | D2: FORMA DE PAGO | E2: DETALLE | F2: TOTAL | G2: =SUM(C4:C1048576) - SUM(B4:B1048576) -> -246804
A4: 45443 | B4: 169284
A6: 45473 | B6: 233261
A8: 45504 | B8: 440987
A9: 45535 | B9: 299109
A10: 45550 | C10: 1142641
A11: 45565 | B11: 263105
A12: 45572 | C12: 263105
A13: 45596 | B13: 313562
A14: 45601 | C14: 313562
A15: 45626 | B15: 559165
A16: 45639 | C16: 559165
A17: 45657 | B17: 198205
A18: 45682 | C18: 198205
A19: 45688 | B19: 616002
A20: 45694 | C20: 616002
A21: 45716 | B21: 799985
A22: 37330 | C22: 799985
A23: 45747 | B23: 416161
A24: 45756 | C24: 416161
A25: 45777 | B25: 282535
A26: 45786 | C26: 282535
A27: 45807 | B27: 242992
A28: 45838 | B28: 172312
A29: 45869 | B29: 392287
A30: 45900 | B30: 376975
A31: 45902 | C31: 1184566
A32: 45930 | B32: 710826
A33: 45961 | B33: 833218
A34: 45991 | B34: 488143
A35: 46002 | C35: 833218
A36: 46013 | C36: 1198969
A37: 46022 | B37: 222886
A38: 46053 | B38: 950898
A39: 46081 | B39: 767152
A40: 46092 | C40: 1694132

Sheet CONTINENTAL
A1: CONTINENTAL y RUCA | D1: volver
A2: FECHA | B2: IMPORTE ADEUDADO | C2: ENTREGAS | D2: FORMA DE PAGO | E2: DETALLE | F2: TOTAL | G2: =SUM(C3:C1048576) - SUM(B3:B1048576) -> 2695136 | H2: =G2 -> 2695136 | J2: PAGO A CTA | K2: 10000000 | L2: EL 5 DEL 10 DEL 2023 ENTREGO 10 CHEQ. DE $1.000.000
C3: 8300000
A4: 45230 | B4: 793651 | E4: CONTINENTAL | J4: DEUDA | K4: 1700000
A5: 45230 | B5: 536722 | E5: RUCA | J5: SALDO A FAVOR | K5: 8300000
A6: 45260 | B6: 793913 | E6: CONTINENTAL | J6: DESDE 01/10/2023 PARA ADELANTE
A7: 45260 | B7: 746625 | E7: RUCA
A8: 45291 | B8: 593763 | E8: CONTINENTAL
A9: 45291 | B9: 628630 | E9: RUCA
A10: 45322 | B10: 603109 | E10: CONTINENTAL
A11: 45322 | B11: 758154 | E11: RUCA
A12: 45351 | B12: 236551 | E12: CONTINENTAL
A13: 45351 | B13: 603806 | E13: RUCA
A14: 45382 | B14: 108383 | E14: CONTINENTAL
A15: 45382 | B15: 336528 | E15: RUCA
A16: 45412 | B16: 186112 | E16: CONTINENTAL
A17: 45412 | B17: 467947 | E17: RUCA
A18: 45443 | B18: 38383 | E18: CONTINENTAL
... A27: 45565 | B27: 1883731 | E27: RUCA
A28: 45576 | C28: 500000 | D28: por diferencia de precios
A29: 45576 | C29: 10000000 | D29: 2 cheq de 5 millones
A30: 45588 | C30: 20000000 | D30: 4 cheq de 5 millones | I30: 45566 | J30: saldo a favor | K30: 25219552
A31: 45596 | B31: 2092984 | E31: RUCA
A32: 45596 | B32: 1757862 | E32: CONTINENTAL
A33: 45626 | B33: 2839086 | E33: RUCA
A34: 45626 | B34: 3196114 | E34: CONTINENTAL
A35: 45657 | B35: 3041547 | E35: RUCA
A36: 45657 | B36: 2162131 | E36: CONTINENTAL
A37: 45688 | B37: 2732526 | E37: ruca | F37: 0.03
A38: 45688 | B38: 1982967 | E38: continental | F38: 0.03
A39: 45716 | B39: 1511407 | E39: ruca | F39: 0.13
A40: 45716 | B40: 1228229 | E40: continental | F40: 0.13
A41: 45747 | B41: 1015501 | E41: RUCA | F41: 0.13
A42: 45747 | B42: 562180 | E42: CONTINENTAL | F42: 0.13
A43: 45777 | B43: 573818 | E43: ruca | F43: 0.26
A44: 45777 | B44: 674871 | E44: continental | F44: 0.26
A45: 45807 | B45: 84577 | E45: ruca
A46: 45807 | B46: 724889 | E46: CONTINENTAL
A47: 45838 | B47: 597174 | E47: RUCA
A48: 45838 | B48: 44728 | E48: CONTINENTAL
...

Sheet CORONADO
A1: CORONADO | D1: volver
A2: FECHA | B2: IMPORTE ADEUDADO | C2: ENTREGAS | D2: FORMA DE PAGO | E2: DETALLE | F2: TOTAL | G2: =SUM(C3:C1048576) - SUM(B3:B1048576) -> -1019581
A4: 45443 | B4: 233724
A5: 45463 | C5: 233724
A6: 45473 | B6: 347127
A7: 45495 | C7: 347200
A8: 45497 | C8: 150000
A9: 45504 | C9: 150000
A10: 45504 | B10: 670007
A11: 45509 | C11: 150000
A12: 45513 | C12: 100000
A13: 45519 | C13: 200000
A14: 45523 | C14: 170000
A15: 45525 | C15: 169934
A16: 45535 | B16: 279402
A17: 45548 | C17: 179402
A18: 45561 | C18: 100000
A19: 45565 | B19: 398845
A20: 45582 | C20: 100000 | D20: efect
A21: 45590 | C21: 150000
A22: 45596 | B22: 481459
A23: 45602 | C23: 100000
A24: 45617 | C24: 100000
A25: 45626 | C25: 100000
A26: 45626 | B26: 377993
A27: 45633 | C27: 209000
A28: 45653 | C28: 100000
A29: 45657 | B29: 395862
A30: 45660 | C30: 100000 | D30: EFECT.
A31: 45667 | C31: 177993
A32: 45676 | C32: 100000
A33: 45684 | C33: 100000
A34: 45689 | B34: 718277
A35: 45690 | C35: 100000
A36: 45693 | C36: 95862
A37: 45706 | C37: 150000
A38: 45713 | C38: 200000
A39: 45716 | B39: 633963
A40: 45718 | C40: 169600
A41: 45364 | C41: 200000
...

Sheet COSTA LAGO
A1: COSTA LAGO | D1: volver
A2: FECHA | B2: IMPORTE ADEUDADO | C2: ENTREGAS | D2: FORMA DE PAGO | E2: DETALLE | F2: TOTAL | G2: =SUM(C3:C1048576) - SUM(B3:B1048576) -> -779358
A4: 45473 | B4: 151434
A5: 45485 | C5: 151434
A6: 45504 | B6: 671964
A7: 45505 | C7: 671964
A8: 45535 | B8: 141399
A9: 45565 | B9: 159810
A10: 45575 | C10: 301209
A11: 45596 | B11: 190847
A12: 45626 | B12: 97356
A13: 45635 | C13: 190847
A14: 45657 | B14: 97086
A15: 45660 | C15: 194442
A16: 45688 | B16: 547100
A17: 45693 | C17: 547100
A18: 45716 | B18: 463503
A19: 45717 | C19: 463503
A20: 45716 | B20: 463503
A21: 45716 | C21: 463503
A22: 45747 | B22: 265701
A23: 45777 | B23: 297944
A24: 45784 | C24: 563645
A25: 45807 | B25: 318941
A26: 45838 | B26: 193731
A27: 45856 | C27: 400000
A28: 45869 | B28: 408034
A29: 45878 | C29: 520706
A30: 45900 | B30: 287842
A31: 45917 | C31: 287842
A32: 45930 | B32: 293492
A33: 45961 | B33: 280424
A34: 45991 | B34: 375986
A35: 46009 | C35: 447000
A36: 46022 | B36: 250998
A37: 46053 | B37: 651508
A38: 46057 | C38: 1150000
A39: 46081 | B39: 523950

Sheet CYBELES
A1: CYBELES | D1: volver
A2: FECHA | B2: IMPORTE ADEUDADO | C2: ENTREGAS | D2: FORMA DE PAGO | E2: DETALLE | F2: TOTAL | G2: =SUM(C3:C1048576) - SUM(B3:B1048576) -> -503463
A4: 45443 | B4: 119203 | E4: cybeles
A5: 45473 | B5: 105640 | E5: cybeles
A6: 45504 | B6: 278620 | E6: cybeles

Sheet DUPLEX
A1: DUPLEX - CYBELES - WYNWOOD | D1: volver
A2: FECHA | B2: IMPORTE ADEUDADO | C2: ENTREGAS | D2: FORMA DE PAGO | E2: DETALLE | F2: TOTAL | G2: =SUM(C3:C1048576) - SUM(B3:B1048576) -> -1515709
A3: saldo anterior | B3: 1319974
A4: 45443 | B4: 158646 | E4: duplex
A5: 45443 | B5: 119203 | E5: cybeles
A6: 45443 | B6: 114534 | E6: madero
A7: 45443 | B7: 41034 | E7: CLARITA
A8: 45443 | B8: 52258 | E8: winwood
A9: 45443 | C9: 500400
A10: 45473 | B10: 226802 | E10: duplex
A11: 45473 | B11: 105640 | E11: cybeles
A12: 45473 | B12: 127254 | E12: madero
A13: 45473 | B13: 130458 | E13: CLARITA
A14: 45473 | B14: 187075 | E14: winwood
A15: 45473 | C15: 803240
A16: 45504 | B16: 357583 | E16: duplex
A17: 45504 | B17: 278620 | E17: cybeles
A18: 45504 | B18: 221087 | E18: madero
A19: 45504 | B19: 246550 | E19: CLARITA
A20: 45504 | B20: 287667 | E20: winwood
A21: 45504 | C21: 406740
A22: 45524 | C22: 604921
A23: 45535 | B23: 128925 | E23: duplex
A24: 45535 | B24: 105858 | E24: cybeles
A25: 45535 | B25: 128125 | E25: madero
A26: 45535 | B26: 33934 | E26: CLARITA
A27: 45535 | B27: 90909 | E27: winwood
A28: 45564 | C28: 1035381 | D28: TRANSF.
A29: 45565 | B29: 247392 | E29: duplex
A30: 45565 | B30: 133948 | E30: cybeles
A31: 45565 | B31: 177758 | E31: madero
A32: 45565 | B32: 132523 | E32: CLARITA
A33: 45565 | B33: 95167 | E33: winwood
A35: 45596 | B35: 330035 | E35: duplex
A36: 45596 | B36: 115152 | E36: cybeles
A37: 45596 | B37: 102174 | E37: madero
A38: 45596 | B38: 192400 | E38: CLARITA
A39: 45596 | B39: 364925 | E39: winwood
A40: 45618 | C40: 204000
A41: 45626 | B41: 365539 | E41: wymwood
...

Sheet EL CONDADO
A1: EL CONDADO | D1: volver
A2: FECHA | B2: IMPORTE ADEUDADO | C2: ENTREGAS | D2: FORMA DE PAGO | E2: DETALLE | F2: TOTAL | G2: =SUM(C3:C1048576) - SUM(B3:B1048576) -> -4458176
C3: 852127
A4: 45412 | B4: 1999700
A5: 45443 | B5: 1698806 | G5: PRECOMPRA ESTUDIANTIL 2024
A6: 45473 | B6: 2259290
A8: 45504 | B8: 2824895
A9: 45510 | C9: 2200000 | D9: (4 E-CHEQ) de 550 mil
A10: 45517 | C10: 800000 | D10: e cheq
A11: 45525 | C11: 1000000 | D11: 2 ECHEQ DE 500
A12: 45535 | B12: 1420425
A13: 45544 | C13: 600000 | D13: FTVO
A14: 45560 | C14: 3750000 | D14: 5 E-CHEQ DE 750
A15: 45565 | B15: 2700234
A16: 45567 | C16: 2352000 | D16: cheq
A17: 45567 | C17: 2295000 | D17: cheq
C18: 2400000 | D18: efect u$d (2.000)
A19: 45596 | B19: 2232305
A20: 45626 | B20: 2826441
A21: 45657 | B21: 2693494
A22: 45667 | C22: 2000000 | D22: EFECT
A23: 45673 | C23: 1500000 | D23: efect
A24: 45686 | C24: 1000000
A25: 45688 | B25: 4296967
A26: 45716 | B26: 4084494
A27: 45723 | C27: 1000000
A28: 45726 | C28: 1000000
A29: 45727 | C29: 1000000
A30: 45728 | C30: 1051920.5
A31: 45741 | C31: 2000000
A32: 45747 | C32: 750000 | D32: E CHEQ
A33: 45747 | C33: 750000 | D33: e cheq
A34: 45747 | B34: 3563289
A35: 45758 | C35: 1300000 | D35: e cheq
A36: 45758 | C36: 3000000 | D36: e cheq
A37: 45777 | B37: 3533981
A38: 45800 | C38: 1000000
A39: 45807 | B39: 3454383
A40: 45821 | C40: 3000000 | D40: e cheq
A41: 45821 | C41: 500000 | D41: transf.
...

Sheet EMBAJADOR
A1: LUAR | D1: volver
A2: FECHA | B2: IMPORTE ADEUDADO | C2: ENTREGAS | D2: FORMA DE PAGO | E2: DETALLE | F2: TOTAL | G2: =SUM(C3:C1048576) - SUM(B3:B1048576) -> 0
A3: 46053 | B3: 359984
A4: 46053 | C4: 359984
A5: 46081 | B5: 340729
A6: 46081 | C6: 340729

Sheet ERNESTINA
A1: ERNESTINA | D1: volver
A2: FECHA | B2: IMPORTE ADEUDADO | C2: ENTREGAS | D2: FORMA DE PAGO | E2: DETALLE | F2: TOTAL | G2: =SUM(C3:C1048576) - SUM(B3:B1048576) -> 0
A4: 45443 | B4: 128015
A5: 45473 | B5: 321479
A6: 45504 | B6: 296576
A7: 45522 | C7: 746070
A8: 45535 | B8: 220443
A9: 45547 | C9: 220443
A10: 45565 | B10: 219360
A11: 45572 | C11: 219360 | D11: TRANSF.
A12: 45596 | B12: 411241
A13: 45601 | C13: 411241
A14: 45626 | B14: 395562
A15: 45632 | C15: 395562
A16: 45657 | B16: 300438
A17: 45674 | C17: 300438
A18: 45688 | B18: 773442
A19: 45700 | C19: 773442
A20: 45716 | B20: 692195
A21: 45726 | C21: 692195
A22: 45747 | B22: 339731
A23: 45777 | B23: 80822
A24: 45808 | B24: 102343
A25: 45812 | C25: 522896
A26: 45838 | B26: 162507
A27: 45869 | B27: 555900
A28: 45876 | C28: 555900
A29: 45900 | B29: 250960
A30: 45929 | C30: 413467
A31: 45930 | B31: 126624
A32: 45961 | B32: 508780
A33: 45972 | C33: 508780
A34: 45991 | B34: 385353
A35: 46000 | C35: 511977
A36: 46022 | B36: 769801
A37: 46035 | C37: 769801
A38: 46053 | B38: 1061356
A39: 46060 | C39: 1061356
A40: 46081 | B40: 1233319
A41: 46097 | C41: 1233319

Sheet GALA
A1: GALA | D1: volver
A2: FECHA | B2: IMPORTE ADEUDADO | C2: ENTREGAS | D2: FORMA DE PAGO | E2: DETALLE | F2: TOTAL | G2: =SUM(C3:C1048576) - SUM(B3:B1048576) -> 101165
A4: 45443 | B4: 292942
A5: 45458 | C5: 292942 | D5: efec
A6: 45473 | B6: 254377
A7: 45490 | C7: 254377 | D7: efec
A8: 45504 | B8: 845222
A9: 45513 | C9: 845222 | D9: efec
A10: 45535 | B10: 323000
A11: 45546 | C11: 323000
A12: 45565 | B12: 490201
A13: 45568 | C13: 490201
A14: 45595 | B14: 570721
A15: 45601 | C15: 570721
A16: 45626 | B16: 484927
A17: 45644 | C17: 484927
A18: 45657 | B18: 456393
A19: 45667 | C19: 456393
A20: 45688 | B20: 948035
A21: 45700 | C21: 948035
A22: 45716 | B22: 886074
A23: 45727 | C23: 886074
A24: 45747 | B24: 575326
A25: 45753 | C25: 575326
A26: 45777 | B26: 370811
A27: 45789 | C27: 370811
A28: 45807 | B28: 530153
A29: 45825 | C29: 530153
A30: 45838 | B30: 294957
A31: 45848 | C31: 294957
A32: 45869 | B32: 618112
A33: 45887 | C33: 618112
A34: 45900 | B34: 490300
A35: 45917 | C35: 490300
A36: 45930 | B36: 443466
A37: 45941 | C37: 443466
A38: 45961 | B38: 567998
A39: 45974 | C39: 567998
A40: 45991 | B40: 485592
A41: 45976 | C41: 485592
...

Sheet ESTILO
A1: ESTILO | D1: volver
A2: FECHA | B2: IMPORTE ADEUDADO | C2: ENTREGAS | D2: FORMA DE PAGO | E2: DETALLE | F2: TOTAL | G2: =SUM(C3:C1048576) - SUM(B3:B1048576) -> 0
A4: 45443 | B4: 1113691
A5: 45451 | C5: 1113691
A6: 45473 | B6: 1770428
A7: 45479 | C7: 1770428
A8: 45504 | B8: 2950541
A9: 45481 | C9: 2950541
A10: 45535 | B10: 1424981
A11: 45540 | C11: 1424981
A12: 45565 | B12: 1967934
A13: 45568 | C13: 1967934
A14: 45626 | B14: 1762356
A15: 45601 | C15: 1762356
A16: 45626 | B16: 3176043
A17: 45631 | C17: 3176043
A18: 45657 | B18: 1741724
A19: 45672 | C19: 1741724
A20: 45688 | B20: 5114395
A21: 45693 | C21: 5114395
A22: 45716 | B22: 4977802
A23: 45737 | C23: 4977802
A24: 45747 | B24: 2780440
A25: 45750 | C25: 2780440
A26: 45777 | B26: 2774357
A27: 45786 | C27: 2774357
A28: 45807 | B28: 2485793
A29: 45823 | C29: 2485793
A30: 45838 | B30: 1947231
A31: 45843 | C31: 1947231
A32: 45869 | B32: 4426003
A33: 45876 | C33: 4426003
A34: 45900 | B34: 3377484
A35: 45908 | C35: 3377484
A36: 45930 | B36: 4585926
A37: 45937 | C37: 4585926
A38: 45961 | B38: 4425854
A39: 45966 | C39: 4425854
A40: 45991 | B40: 4661690
A41: 46000 | C41: 4661690
...

Sheet GOLDEN ROSS
A1: CASEROS 248 | D1: volver
A2: FECHA | B2: IMPORTE ADEUDADO | C2: ENTREGAS | D2: FORMA DE PAGO | E2: DETALLE | F2: TOTAL | G2: =SUM(C3:C1048576) - SUM(B3:B1048576) -> 0
A4: 46022 | B4: 5125320
A5: 46031 | C5: 5125320
A6: 46053 | B6: 5960481
A7: 46066 | C7: 5960481
A8: 46081 | B8: 7111334
A9: 46097 | C9: 7111334

Sheet HOTEL 376
A1: HOTEL 376 | D1: volver
A2: FECHA | B2: IMPORTE ADEUDADO | C2: ENTREGAS | D2: FORMA DE PAGO | E2: DETALLE | F2: TOTAL | G2: =SUM(C3:C1048576) - SUM(B3:B1048576) -> -2769039
A4: 45412 | B4: 809757
A5: 45427 | C5: 809757 | D5: cheq fis
A6: 45443 | B6: 530194
A7: 45452 | C7: 530194 | D7: cheq fis
A8: 45473 | B8: 1420739
A9: 45488 | C9: 1420739 | D9: efect.
A10: 45504 | B10: 3869104
A11: 45535 | B11: 1126619
A12: 45538 | C12: 3325000 | D12: 2 CHEQUES
A13: 45565 | B13: 2393148
A14: 45626 | B14: 1762356 | C14: 500000 | D14: transf
A15: 45576 | C15: 3200000 | D15: 2 CHEQUES
A16: 45596 | B16: 2510871
A17: 45616 | C17: 1920500
A18: 45626 | B18: 4024512
A19: 45632 | C19: 3000000 | D19: transf.
A20: 45647 | C20: 4727272 | D20: CHEQUE
A21: 45657 | B21: 3368395
A22: 45659 | C22: 2275073
A23: 45688 | B23: 3543132
A24: 45710 | C24: 3550000
A25: 45716 | B25: 2941523
A26: 45727 | C26: 1000000
A27: 45747 | B27: 1920048
A28: 45751 | C28: 700000 | D28: CHEQUE
A29: 45751 | C29: 1127000 | D29: EFECTIVO
A30: 45777 | B30: 1798911
A31: 45783 | C31: 2000000
A32: 45804 | C32: 2300000
A33: 45807 | B33: 1171885
A34: 45838 | B34: 1640380
A35: 45839 | C35: 2300000
A36: 45869 | B36: 3863469
A37: 45875 | C37: 3033200 | D37: cheque
A38: 45875 | C38: 717952 | D38: cheque
A39: 45900 | B39: 1148213
A40: 45924 | C40: 2600000
A41: 45930 | B41: 2829088
...

Sheet IMPERIAL
A1: IMPERIAL | D1: volver
A2: FECHA | B2: IMPORTE ADEUDADO | C2: ENTREGAS | D2: FORMA DE PAGO | E2: DETALLE | F2: TOTAL | G2: =SUM(C3:C1048576) - SUM(B3:B1048576) -> -64227
A5: 45504 | B5: 400915
A6: 45525 | C6: 400915
A7: 45684 | B7: 521392
A8: 45700 | C8: 521392
A9: 45716 | B9: 246337
A10: 45742 | C10: 246337
A11: 45747 | B11: 1047840
A12: 45777 | C12: 1200485 | D12: cheques
A13: 45777 | B13: 152645
A14: 46022 | B14: 64227
A15: 46038 | B15: 601862
A16: 46049 | C16: 601862
A17: 46053 | B17: 469412
A18: 46063 | C18: 469412
A19: 46068 | B19: 665678
A20: 46081 | B20: 422421
A21: 46073 | C21: 665678
A22: 46092 | C22: 422421

Sheet INTERLAC
A1: INTERLAC | D1: volver
A2: FECHA | B2: IMPORTE ADEUDADO | C2: ENTREGAS | D2: FORMA DE PAGO | E2: DETALLE | F2: TOTAL | G2: =SUM(C3:C1048576) - SUM(B3:B1048576) -> -5189294
A4: 45443 | B4: 224579
A5: 45473 | B5: 492396
A6: 45504 | B6: 1026558
A7: 45517 | C7: 1000000
A8: 45531 | C8: 300000
A9: 45535 | B9: 882957
A10: 45565 | B10: 1759822
A11: 45588 | C11: 1000000
A12: 45596 | B12: 1669846
A13: 45602 | C13: 1000000
A14: 45624 | C14: 1000000
A15: 45626 | B15: 1762356
A16: 45648 | C16: 500000
A17: 45657 | B17: 2458214
A18: 45293 | C18: 1500000
A19: 45674 | C19: 2000000
A20: 45679 | C20: 700000
A21: 45688 | B21: 2299995
A22: 45716 | B22: 2337809
A23: 45721 | C23: 2470000
A24: 45742 | C24: 1723150 | D24: cheques
A25: 45747 | B25: 1073783
A26: 45777 | B26: 1220988
A27: 45782 | C27: 1000000 | D27: EFT
A28: 45782 | C28: 500000 | D28: cheques
A29: 45807 | B29: 194872
A30: 45812 | C30: 1000000 | D30: eft
A31: 45833 | C31: 1500000
A32: 45838 | B32: 1518216
A33: 45854 | C33: 1000000
A34: 45869 | B34: 1997044
A35: 45875 | C35: 1000000
A36: 45889 | C36: 1000000
A37: 45900 | B37: 2016024
A38: 45917 | C38: 1000000
A39: 45930 | B39: 2736161
A40: 45950 | C40: 1000000
A41: 45957 | C41: 1000000
...

Sheet INTI HUASI
A1: INTI HUASI-LAGO AZUL-CONDOR-NEVADO | D1: volver
A2: FECHA | B2: IMPORTE ADEUDADO | C2: ENTREGAS | D2: FORMA DE PAGO | E2: DETALLE | F2: TOTAL | G2: =SUM(C3:C1048576) - SUM(B3:B1048576) -> -35059823
A4: 24/1 -- 21/3 | B4: 1375032 | C4: 136595 | E4: CONDOR
A5: 24/1 -- 21/3 | B5: 1150164 | C5: 1000000 | E5: NEVADO
A6: 24/1 -- 21/3 | B6: 1025692 | C6: 1830000 | D6: IVA FEB-MARZ-ABRIL | E6: LAGO AZUL
A7: 24/1 -- 21/3 | B7: 147328 | E7: INTI HUASI
C8: 510000 | D8: IVA MAYO
C9: 0 | D9: IVA JUNIO
C10: 1500000 | D10: IVA JULIO
A11: 22/3--7/8 | B11: 553083 | E11: CONDOR
A12: 22/3--7/8 | B12: 2635727 | E12: NEVADO
A13: 22/3--7/8 | B13: 2076870 | E13: LAGO AZUL
A14: 22/3--7/8 | B14: 453505 | E14: INTI HUASI
A15: 45545 | C15: 900000 | D15: IVA AGOSTO
A16: 45553 | C16: 3000000 | D16: 2CHEQ DE 1,5
A17: 8/8 al 27/10 | B17: 1177142 | E17: NEVADO
A18: 8/8 al 27/10 | B18: 895244 | E18: LAGO AZUL
A19: 8/8 al 27/10 | B19: 257856 | E19: INTI HUASI
A20: 45536 | C20: 1200000 | D20: IVA SEPT
A21: 45566 | C21: 1800000 | D21: IVA OCT
A22: 28/10 al 26/1 | B22: 1157562 | E22: LAGO AZUL
A23: 28/10 al 26/1 | B23: 460974 | E23: INTI HUASI
A24: 01/09 AL 26/1 | B24: 3768000 | E24: CAÑITAS
A25: 45332 | C25: 4000000 | D25: CHEQ
A26: 45698 | C26: 415000 | D26: CHEQ
A27: 45701 | C27: 1500000 | D27: IVA ENERO
C28: 1500000 | D28: IVA FEBRERO
C29: 0 | D29: IVA MARZO
C30: 0 | D30: IVA ABRIL
C31: 900000 | D31: IVA MAYO
C32: 600000 | D32: IVA JUNIO
A33: 27/01 al 08/07 | B33: 582445 | E33: INTI HUASI
A34: 27/01 al 08/07 | B34: 228244 | E34: NEVADO
A35: 27/01 al 08/07 | B35: 1616796 | E35: LAGO AZUL
A36: 27/01 al 08/07 | B36: 4823009 | E36: CAÑITAS
A37: 09/07 al 07/09 | B37: 112193 | E37: NEVADO
C38: 1200000 | D38: IVA AGOSTO
C39: 1200000 | D39: IVA SEPT
A40: 09/07 al 04/01 | B40: 992852 | E40: LAGO AZUL
A41: 09/07 al 04/01 | B41: 8951157 | E41: CAÑITAS
...

Sheet LAGO AZUL
A1: LAGO AZUL | D1: volver
A2: FECHA | B2: IMPORTE ADEUDADO | C2: ENTREGAS | D2: FORMA DE PAGO | E2: DETALLE | F2: TOTAL | G2: =SUM(C3:C1048576) - SUM(B3:B1048576) -> 0

Sheet LAKE DOMUS
A1: LAKE DOMUS | D1: volver
A2: FECHA | B2: IMPORTE ADEUDADO | C2: ENTREGAS | D2: FORMA DE PAGO | E2: DETALLE | F2: TOTAL | G2: =SUM(C3:C1048576) - SUM(B3:B1048576) -> 0
A4: 45473 | B4: 1093120
A5: 45504 | B5: 1677690
A6: 45533 | C6: 2770810
A7: 45535 | B7: 1632720
A8: 45565 | B8: 1823658
A9: 45596 | B9: 2681519
A10: 45607 | C10: 6137897
A11: 45626 | B11: 5630224
A12: 45649 | C12: 2500000 | D12: E CHEQ
A13: 45657 | B13: 6548333
A14: 45664 | C14: 9678557
A15: 45688 | B15: 4564202
A16: 45716 | B16: 4943754
A17: 45738 | C17: 9507956
A18: 45747 | B18: 2664145
A19: 45770 | C19: 2664145 | D19: CHEQUES
A20: 45777 | B20: 2938412
A21: 45807 | B21: 1810524
A22: 45818 | C22: 4748937
A23: 45838 | B23: 1435000
A24: 45855 | C24: 1434999
A25: 45869 | B25: 2593187
A26: 45880 | C26: 3000000 | D26: cheques
A27: 45900 | B27: 2917664
A28: 45929 | C28: 2510851 | D28: CHEQUES
A29: 45930 | B29: 4223908
A30: 45945 | C30: 4223908 | D30: CHEQUES
A31: 45961 | B31: 4419926
A32: 45972 | C32: 4419926 | D32: cheques
A33: 45991 | B33: 8955400
A34: 46002 | C34: 8955400 | D34: cheques
A35: 46022 | B35: 9039827
A36: 46036 | C36: 9039827 | D36: CHEQUES
A37: 46053 | B37: 7770251
A38: 46070 | C38: 7770251 | D38: CHEQUES
A39: 46081 | B39: 5878352
A40: 46097 | C40: 5878352

Sheet LE MIRAGE
A1: LE MIRAGE | D1: volver
A2: FECHA | B2: IMPORTE ADEUDADO | C2: ENTREGAS | D2: FORMA DE PAGO | E2: DETALLE | F2: TOTAL | G2: =SUM(C3:C1048576) - SUM(B3:B1048576) -> -2950168
A4: 45473 | B4: 1679058
A5: 45492 | C5: 1400000
A6: 45504 | B6: 2746806
A7: 45513 | C7: 600000
A8: 45520 | C8: 800000
A9: 45527 | C9: 800000
A10: 45533 | C10: 825864
A11: 45535 | B11: 1398817
A12: 45541 | C12: 500000
A13: 45548 | C13: 500000
A14: 45555 | C14: 300000
A15: 45562 | C15: 98817
A16: 45565 | B16: 1806473
A17: 45574 | C17: 500000
A18: 45582 | C18: 500000
A19: 45583 | C19: 353040
A20: 45583 | C20: 87120
A21: 45596 | B21: 2751363
A22: 45608 | C22: 366314
A23: 45618 | C23: 500000
A24: 45625 | C24: 1500000
A25: 45626 | B25: 2715547
A26: 45638 | C26: 400000
A27: 45632 | C27: 400000
A28: 45643 | C28: 500000
A29: 45652 | C29: 1000000
A30: 45657 | B30: 2295858
C31: 1000000
A32: 45667 | C32: 1000000
A33: 45674 | C33: 500000
A34: 45685 | C34: 500000
A35: 45688 | B35: 3951208
A36: 45688 | C36: 426768
A37: 45700 | C37: 800000
A38: 45714 | C38: 1000000
A39: 45716 | B39: 3049683
A40: 45721 | C40: 1000000
A41: 45723 | C41: 1151208
...

Sheet LUCAS
A1: CAUPLAS | D1: volver
A2: FECHA | B2: IMPORTE ADEUDADO | C2: ENTREGAS | D2: FORMA DE PAGO | E2: DETALLE | F2: TOTAL | G2: =SUM(C3:C1048576) - SUM(B3:B1048576) -> 0
A3: 45991 | B3: 217800
A4: 46022 | B4: 653400
A5: 46032 | B5: 735354.38
A6: 46046 | C6: 1606554.4

Sheet MADERO
A1: MADERO | D1: volver
A2: FECHA | B2: IMPORTE ADEUDADO | C2: ENTREGAS | D2: FORMA DE PAGO | E2: DETALLE | F2: TOTAL | G2: =SUM(C3:C1048576) - SUM(B3:B1048576) -> 0
A3: 45900 | B3: 167400
A4: 45903 | C4: 167400
A5: 45930 | B5: 214206
A6: 45959 | C6: 214206
A7: 45961 | B7: 300716
C8: 300716

Sheet MARBOT
A1: COLONIA DE TANTI | D1: volver
A2: FECHA | B2: IMPORTE ADEUDADO | C2: ENTREGAS | D2: FORMA DE PAGO | E2: DETALLE | F2: TOTAL | G2: =SUM(C3:C1048576) - SUM(B3:B1048576) -> 0
A3: 46081 | B3: 1007214
A4: 46092 | C4: 1007214

Sheet MIRADOR DE LA VILLA
A1: MIRADOR DE LA VILLA | D1: volver
A2: FECHA | B2: IMPORTE ADEUDADO | C2: ENTREGAS | D2: FORMA DE PAGO | E2: DETALLE | F2: TOTAL | G2: =SUM(C3:C1048576) - SUM(B3:B1048576) -> 909967
A4: 45443 | B4: 74616
A5: 45458 | C5: 74616
A6: 45473 | B6: 505860
A7: 45486 | C7: 505860
A8: 45504 | B8: 567953
A9: 45506 | C9: 567953
A10: 45535 | B10: 157186
A11: 45546 | C11: 157186
A12: 45565 | B12: 720984
A13: 45573 | C13: 720984 | D13: 200 FT Y 500 CHEQ
A14: 45596 | B14: 2323088
A15: 45598 | C15: 2323088
A16: 45626 | B16: 4547691
A17: 45630 | C17: 4661000 | D17: 3 cheques
A18: 45657 | B18: 3874544
A19: 45659 | C19: 3761235
A20: 45688 | B20: 4382082
A21: 45690 | C21: 4382082
A22: 45716 | B22: 2154065
A23: 45728 | C23: 2154065
A24: 45747 | B24: 2991353
A25: 45752 | C25: 2991353
A26: 45762 | C26: 500000
A27: 45766 | C27: 500000
A28: 45769 | C28: 500000
A29: 45772 | C29: 400000
A30: 45777 | B30: 2281473
A31: 45796 | C31: 381473
A32: 45807 | B32: 496870
A33: 45815 | C33: 496870
A34: 45834 | C34: 500000
A35: 45838 | B35: 605483
A36: 45843 | C36: 105483
A37: 45854 | C37: 800000
A38: 45860 | C38: 800000
A39: 45869 | B39: 1728263
A40: 45875 | C40: 128263
A41: 45881 | C41: 1000000
...

Sheet MIRADOR DE LAS SIERRAS
A1: MIRADOR DE LAS SIERRAS | D1: volver
A2: FECHA | B2: IMPORTE ADEUDADO | C2: ENTREGAS | D2: FORMA DE PAGO | E2: DETALLE | F2: TOTAL | G2: =SUM(C3:C1048576) - SUM(B3:B1048576) -> 0
A4: 1/7 al 7/8 | B4: 352199
C5: 352199 | D5: transf a jere
A6: 8/8 AL 5/9 | B6: 402607
A7: 45540 | C7: 402607
A8: 45588 | B8: 716000 | C8: 716000
A9: 45716 | B9: 1108965 | C9: 1108965
A10: 45807 | B10: 660000 | C10: 660000
A11: 45869 | B11: 982000 | C11: 982000
A12: 46028 | B12: 528000 | C12: 528000
A13: 46053 | B13: 1105017
A14: 46049 | C14: 1105017
A15: 46077 | B15: 1460000
A16: 46077 | C16: 1460000

Sheet MIRADOR DEL NEVADO
A1: MIRADOR DEL NEVADO | D1: volver
A2: FECHA | B2: IMPORTE ADEUDADO | C2: ENTREGAS | D2: FORMA DE PAGO | E2: DETALLE | F2: TOTAL | G2: =SUM(C3:C1048576) - SUM(B3:B1048576) -> 0

Sheet MONTECATINI
A1: MONTECATINI | D1: volver
A2: FECHA | B2: IMPORTE ADEUDADO | C2: ENTREGAS | D2: FORMA DE PAGO | E2: DETALLE | F2: TOTAL | G2: =SUM(C3:C1048576) - SUM(B3:B1048576) -> -271779
A4: 45504 | B4: 371779
A5: 45510 | C5: 100000

Sheet MORADILLO
A1: MORADILLO | D1: volver
A2: FECHA | B2: IMPORTE ADEUDADO | C2: ENTREGAS | D2: FORMA DE PAGO | E2: DETALLE | F2: TOTAL | G2: =SUM(C3:C1048576) - SUM(B3:B1048576) -> 0
A4: 45382 | B4: 86994
A5: 45397 | C5: 85000
A6: 45412 | B6: 60775
A7: 45443 | B7: 87972
A8: 45473 | B8: 68850 | C8: 217597
A9: 45504 | B9: 99994
A10: 45525 | C10: 101988
A11: 45535 | B11: 91396
A12: 45553 | C12: 91396
A13: 45565 | B13: 87373
A14: 45576 | C14: 87373
A15: 45596 | B15: 185058
A16: 45626 | B16: 62137
A17: 45646 | C17: 150000
A18: 46018 | C18: 97200
A19: 45657 | B19: 139557
A20: 45676 | C20: 139557
A21: 45688 | B21: 192798
A22: 45700 | C22: 192798
A23: 45716 | B23: 221154
A24: 45726 | C24: 221149
A25: 45747 | B25: 99505
A26: 45728 | C26: 99505
A27: 45777 | B27: 181620
A28: 45807 | C28: 181620
A29: 45807 | B29: 91879
A30: 45838 | B30: 50656
A31: 45857 | C31: 142535
A32: 45869 | B32: 162979
A33: 45880 | C33: 162979
A34: 45900 | B34: 118540
A35: 45930 | B35: 64422
A36: 45937 | C36: 118500
A37: 45961 | B37: 104372
A38: 45980 | C38: 104372
A39: 45986 | C39: 64462
A40: 45991 | B40: 191497
A41: 46022 | B41: 45646
...

Sheet NAZARETH
A1: NAZARETH | D1: volver
A2: FECHA | B2: IMPORTE ADEUDADO | C2: ENTREGAS | D2: FORMA DE PAGO | E2: DETALLE | F2: TOTAL | G2: =SUM(C3:C1048576) - SUM(B3:B1048576) -> 0
A4: 12/7 al 23/7 | B4: 240585
A5: 45498 | C5: 240585
A6: 45716 | B6: 830875
A7: 46052 | C7: 830875
A8: 46081 | B8: 691906
A9: 46091 | C9: 691906

Sheet PANORAMA
A1: PANORAMA | D1: volver
A2: FECHA | B2: IMPORTE ADEUDADO | C2: ENTREGAS | D2: FORMA DE PAGO | E2: DETALLE | F2: TOTAL | G2: =SUM(C3:C1048576) - SUM(B3:B1048576) -> 0
A4: 45382 | B4: 967970
A5: 45412 | B5: 457983
A6: 45443 | B6: 321064
A7: 45473 | B7: 338412
A8: 45488 | C8: 2085429
A9: 45504 | B9: 1084961
A10: 45535 | B10: 485991
A11: 45565 | B11: 544829
A12: 45596 | B12: 576532
A13: 45626 | B13: 492644
A14: 45637 | C14: 2115781
A15: 45657 | B15: 525816
A16: 45688 | B16: 1980389
A17: 45705 | C17: 1594992
A18: 45716 | B18: 1803334
A19: 45747 | B19: 1156945
A20: 45755 | C20: 3783723
A21: 45777 | B21: 604624
A22: 45807 | B22: 322515
A23: 45838 | B23: 601772
A24: 45846 | C24: 2084086
A25: 45869 | B25: 1791015
A26: 45900 | B26: 896098
A27: 45902 | C27: 2392787
A28: 45930 | B28: 940860
A29: 45961 | B29: 728835
A30: 45973 | C30: 896098
A31: 45991 | B31: 669042
A32: 46002 | C32: 940860
A33: 46022 | B33: 939852
A34: 46031 | C34: 1397877
A35: 46053 | B35: 2374511
A36: 46070 | C36: 939852
A37: 46077 | C37: 2374509
A38: 46081 | B38: 2478304
A39: 46098 | C39: 2478304

Sheet PARQUE
A1: CATEDRAL | D1: volver
A2: FECHA | B2: IMPORTE ADEUDADO | C2: ENTREGAS | D2: FORMA DE PAGO | E2: DETALLE | F2: TOTAL | G2: =SUM(C3:C1048576) - SUM(B3:B1048576) -> -4349719
A3: 45991 | B3: 1952754
A4: 45992 | C4: 1000000
A5: 46022 | B5: 826000
A6: 46053 | B6: 1689963
A7: 46080 | C7: 1000000
A8: 46081 | B8: 1881002

Sheet PINARES CERRO HOTEL
A1: PINARES CERRO HOTEL | D1: volver
A2: FECHA | B2: IMPORTE ADEUDADO | C2: ENTREGAS | D2: FORMA DE PAGO | E2: DETALLE | F2: TOTAL | G2: =SUM(C3:C1048576) - SUM(B3:B1048576) -> 0
A4: 45473 | B4: 1857882
C5: 1857882
A6: 45504 | B6: 3467986
A7: 45526 | C7: 3467986
A8: 45535 | B8: 889259
A9: 45552 | C9: 889259
A10: 45565 | B10: 1761518
A11: 45585 | C11: 1761518
A12: 45596 | B12: 1599888
A13: 45621 | C13: 1599888
A14: 45626 | B14: 1978379
A15: 45643 | C15: 1978379
A16: 45657 | B16: 2706797
A17: 45672 | C17: 2706797
A18: 45688 | B18: 4374775
A19: 45716 | B19: 3759192
A20: 45737 | C20: 8133967
A21: 45747 | B21: 3080691
A22: 45762 | C22: 3080691
A23: 45777 | B23: 2694753
A24: 45438 | C24: 2694753
A25: 45807 | B25: 1933124
A26: 45823 | C26: 1933124
A27: 45838 | B27: 2322217
A28: 45848 | C28: 2322217
A29: 45869 | B29: 4089008
A30: 45873 | C30: 61339 | D30: NC
A31: 45888 | C31: 4027669
A32: 45900 | B32: 2700903
A33: 45919 | C33: 2700903
A34: 45930 | B34: 2822160
A35: 45947 | C35: 2822160
A36: 45961 | B36: 3044172
A37: 45981 | C37: 3044172
A38: 45991 | B38: 3854207
A39: 46010 | C39: 3854207
A40: 46022 | B40: 3906463
A41: 46037 | C41: 3906463
...

Sheet PINARES CERRO MANTELERIA
A1: PINARES CERRO MANTELERIA | D1: volver
A2: FECHA | B2: IMPORTE ADEUDADO | C2: ENTREGAS | D2: FORMA DE PAGO | E2: DETALLE | F2: TOTAL | G2: =SUM(C3:C1048576) - SUM(B3:B1048576) -> 0
A4: 45473 | B4: 162862
A5: 45488 | C5: 162862
A6: 45504 | B6: 280713
A7: 45526 | C7: 280713
A8: 45535 | B8: 49871
A9: 45552 | C9: 49871
A10: 45565 | B10: 147902
A11: 45585 | C11: 147902
A12: 45596 | B12: 139647
A13: 45621 | C13: 139647
A14: 45626 | B14: 124081
A15: 45643 | C15: 124081
A16: 45657 | B16: 213959
A17: 45672 | C17: 213959
A18: 45688 | B18: 309087
A19: 45716 | B19: 266146
A20: 45737 | C20: 575233
A21: 45747 | B21: 183964
A22: 45762 | C22: 183964
A23: 45777 | B23: 174380
A24: 45803 | C24: 174380
A25: 45807 | B25: 169251
A26: 45823 | C26: 169251
A27: 45838 | B27: 156304
A28: 45848 | C28: 156304
A29: 45869 | B29: 372719
A30: 45888 | C30: 372719
A31: 45900 | B31: 201294
A32: 45919 | C32: 201294
A33: 45930 | B33: 221182
A34: 45947 | C34: 221182
A35: 45961 | B35: 141840
A36: 45981 | C36: 141840
A37: 45991 | B37: 318541
A38: 46010 | C38: 318541
A39: 46022 | B39: 159144
A40: 46037 | C40: 159144
A41: 46053 | B41: 547382
...

Sheet PINARES PANORAMA HOTEL
A1: PINARES PANORAMA HOTEL | D1: volver
A2: FECHA | B2: IMPORTE ADEUDADO | C2: ENTREGAS | D2: FORMA DE PAGO | E2: DETALLE | F2: TOTAL | G2: =SUM(C3:C1048576) - SUM(B3:B1048576) -> 0
A4: 45473 | B4: 2535689
A5: 45488 | C5: 2535689
A6: 45504 | B6: 4117477
A7: 45526 | C7: 4117477
A8: 45535 | B8: 2815464
A9: 45552 | C9: 2815464
A10: 45565 | B10: 3612334
A11: 45585 | C11: 3612334
A12: 45596 | B12: 2893718
A13: 45621 | C13: 2893718
A14: 45626 | B14: 3022508
A15: 45643 | C15: 3022508
A16: 45657 | B16: 3468335
A17: 45672 | C17: 3468335
A18: 45688 | B18: 5211710
A19: 45716 | B19: 4364752
A20: 45737 | C20: 9576462
A21: 45747 | B21: 3494475
A22: 45762 | C22: 3494475
A23: 45777 | B23: 3804093
A24: 45803 | C24: 3804093
A25: 45807 | B25: 4283815
A26: 45823 | C26: 4283815
A27: 45838 | B27: 4382982
A28: 45848 | C28: 4382982
A29: 45869 | B29: 5936520
A30: 45873 | C30: 19720 | D30: NC
A31: 45888 | C31: 5916800
A32: 45900 | B32: 3482565
A33: 45919 | C33: 3482565
A34: 45930 | B34: 4711343
A35: 45947 | C35: 4711343
A36: 45961 | B36: 4861187
A37: 45981 | C37: 4861187
A38: 45991 | B38: 4912768
A39: 46010 | C39: 4912768
A40: 46022 | B40: 4639078
A41: 46037 | C41: 4639078
...

Sheet PINARES PANORAMA MANTELERIA
A1: PINARES PANORAMA MANTELERIA | D1: volver
A2: FECHA | B2: IMPORTE ADEUDADO | C2: ENTREGAS | D2: FORMA DE PAGO | E2: DETALLE | F2: TOTAL | G2: =SUM(C3:C1048576) - SUM(B3:B1048576) -> 0
A4: 45473 | B4: 202471
A5: 45488 | C5: 202471
A6: 45504 | B6: 321056
A7: 45526 | C7: 321056
A8: 45535 | B8: 224625
A9: 45552 | C9: 224625
A10: 45565 | B10: 246833
A11: 45585 | C11: 246833
A12: 45596 | B12: 399672
A13: 45621 | C13: 399672
A14: 45626 | B14: 303351
A15: 45643 | C15: 303351
A16: 45657 | B16: 209269
A17: 45672 | C17: 209269
A18: 45688 | B18: 314551
A19: 45716 | B19: 237920
A20: 45737 | C20: 552471
A21: 45747 | B21: 301542
A22: 45762 | C22: 301542
A23: 45777 | B23: 311420
A24: 45803 | C24: 311420
A25: 45807 | B25: 327310
A26: 45823 | C26: 327310
A27: 45838 | B27: 403941
A28: 45848 | C28: 403941
A29: 45869 | B29: 509763
A30: 45873 | C30: 49035
A31: 45888 | C31: 460728
A32: 45900 | B32: 242802
A33: 45919 | C33: 242802
A34: 45930 | B34: 397059
A35: 45947 | C35: 397059
A36: 45961 | B36: 440938
A37: 45981 | C37: 440938
A38: 45991 | B38: 530466
A39: 46010 | C39: 530466
A40: 46022 | B40: 281363
A41: 46037 | C41: 281363
...

Sheet POSADA DEL ANGEL
A1: TANTO | D1: volver
A2: FECHA | B2: IMPORTE ADEUDADO | C2: ENTREGAS | D2: FORMA DE PAGO | E2: DETALLE | F2: TOTAL | G2: =SUM(C3:C1048576) - SUM(B3:B1048576) -> 0
A3: 46022 | B3: 156464
A4: 46024 | C4: 156464

Sheet PRESIDENTE
A1: PRESIDENTE | D1: volver
A2: FECHA | B2: IMPORTE ADEUDADO | C2: ENTREGAS | D2: FORMA DE PAGO | E2: DETALLE | F2: TOTAL | G2: =SUM(C3:C1048576) - SUM(B3:B1048576) -> -2192686
A4: 45351 | B4: 3516105
A5: 45382 | B5: 3927826
A6: 45412 | B6: 3162808 | C6: 2469966
A7: 45443 | B7: 2714279
C8: 8412773
A9: 45473 | B9: 3122250
A10: 45485 | C10: 1755600
A11: 45504 | B11: 6307870
A12: 45512 | C12: 1000000
A13: 45517 | C13: 460600
A14: 45526 | C14: 1000000
A15: 45535 | B15: 3277230
A16: 45544 | C16: 4000000
A17: 45552 | C17: 1500000 | D17: TRANSF
A18: 45553 | C18: 1000000 | D18: TRANSF
A19: 45565 | B19: 4688607
A20: 45568 | C20: 2376000
A21: 45579 | C21: 2053430 | D21: efect
A22: 45587 | C22: 5000000 | D22: cheque
A23: 45596 | B23: 5965870
A24: 45609 | C24: 2000000
A25: 45625 | C25: 1000000
A26: 45626 | B26: 7303175
A27: 45630 | C27: 2405000 | D27: cheque
A28: 45630 | C28: 1500000 | D28: efect
A29: 45632 | C29: 1000000
A30: 45637 | C30: 1000000
A31: 45657 | B31: 7412641
A32: 45659 | C32: 4052651 | D32: efect
A33: 45673 | C33: 1500000 | D33: efect
A34: 45681 | C34: 1676000 | D34: TRANSF
C35: 2100000 | D35: CHEQUES
A36: 45688 | B36: 8270886
A37: 45705 | C37: 1000000 | D37: TRANSF
A38: 45706 | C38: 3000000 | D38: TRANSF
A39: 45716 | B39: 8681371
A40: 45722 | C40: 1552500 | D40: CHEQUES
A41: 45722 | C41: 4000000 | D41: TRANSF
...

Sheet QUORUM
A1: QUORUM | D1: volver
A2: FECHA | B2: IMPORTE ADEUDADO | C2: ENTREGAS | D2: FORMA DE PAGO | E2: DETALLE | F2: TOTAL | G2: =SUM(C3:C1048576) - SUM(B3:B1048576) -> -9197722.1
A4: 45443 | B4: 3866873
A5: 45460 | C5: 3866873 | D5: E-CHEQ.
A6: 45473 | B6: 3957194
A7: 45504 | B7: 4409112
A8: 45506 | C8: 3957194 | D8: CHEQUES FIS,
A9: 45535 | B9: 5997533
A10: 45537 | C10: 4409112
A11: 45565 | B11: 5461758
A12: 45579 | C12: 3540000
A13: 45581 | C13: 2101478
A14: 45581 | C14: 356055
A15: 45596 | B15: 5897702
A16: 45603 | C16: 5461758
A17: 45625 | C17: 5897702
A18: 45626 | B18: 6895033
A19: 45657 | B19: 5834449
A20: 45660 | C20: 7836811 | D20: E-CHEQ
A21: 45688 | B21: 4446018
A22: 45716 | B22: 5732594
A23: 45721 | C23: 4892671 | D23: E-CHEQ.
A24: 45734 | C24: 7641493.1 | D24: E-CHEQ.
A25: 45747 | B25: 6702730
A26: 45777 | B26: 6183803
A27: 45790 | C27: 8951117.5 | D27: E-CHEQ.
A28: 45803 | C28: 111300 | D28: NC ABRIL
A29: 45807 | B29: 6811709
A30: 45835 | C30: 2334000 | D30: CHEQUES
A31: 45835 | C31: 6589887.7 | D31: E-CHEQ.
A32: 45838 | B32: 5685883
A33: 45865 | C33: 264107 | D33: NC MAYO
A34: 45869 | B34: 6789472
A35: 45877 | C35: 20000000
A36: 45900 | B36: 6861124
A37: 45930 | B37: 8841464
A38: 45939 | C38: 2491182.7
A39: 45961 | B39: 7828100
A40: 45974 | C40: 8841464
A41: 45991 | B41: 8976822
...

Sheet RANQUELES 
A1: RANQUELES | D1: volver
A2: FECHA | B2: IMPORTE ADEUDADO | C2: ENTREGAS | D2: FORMA DE PAGO | E2: DETALLE | F2: TOTAL | G2: =SUM(C3:C1048576) - SUM(B3:B1048576) -> 0
A4: 45443 | B4: 207034
A5: 45473 | B5: 303198
A6: 45479 | C6: 207034 | D6: TRANSF.
A7: 45479 | C7: 303198 | D7: TRANSF.
A8: 45504 | B8: 678722
A9: 45517 | C9: 678722
A10: 45535 | B10: 82236
A11: 45565 | B11: 650105
A12: 45585 | C12: 732341
A13: 45596 | B13: 1241875
A14: 45615 | C14: 1400000
A15: 45626 | B15: 1456500
A16: 45649 | C16: 2070000
A17: 45657 | B17: 1416715
A18: 45688 | B18: 2351305
A19: 45706 | C19: 2996395
A20: 45716 | B20: 1524109
A21: 45738 | C21: 1524109
A22: 45747 | B22: 736278
A23: 45777 | B23: 403966
A24: 45791 | C24: 1140244
A25: 45807 | B25: 79556
A26: 45826 | C26: 79556
A27: 45838 | B27: 113446
A28: 45862 | C28: 113446
A29: 45869 | B29: 1039148
A30: 45884 | C30: 1039148
A31: 45900 | B31: 287978
A32: 45905 | C32: 287978
A33: 45930 | B33: 1137093
A34: 45933 | C34: 1137093
A35: 45961 | B35: 1587905
A36: 45991 | B36: 2420301
A37: 45995 | C37: 3380000 | D37: cheques
A38: 46022 | B38: 1932035
A39: 46030 | C39: 1932035
A40: 46042 | C40: 628208
A41: 46053 | B41: 3922599
...

Sheet RIVIERA
A1: RIVIERA | D1: volver
A2: FECHA | B2: IMPORTE ADEUDADO | C2: ENTREGAS | D2: FORMA DE PAGO | E2: DETALLE | F2: TOTAL | G2: =SUM(C17:C64) - SUM(B17:B64) -> -387025 | I2: PAGO A CTA | J2: 10000000 | K2: EL 01/02/2024 ENTREGARON $10.000.000 A CTA DE HOTEL RIVIERA
I3: SALDO | J3: =G2 -> -387025
A4: 45351 | B4: 1745279 | I4: DESDE 01/02/2024 PARA ADELANTE
A5: 45382 | B5: 891193
A6: 45412 | B6: 997185
A7: 45443 | B7: 917808
A8: 45473 | B8: 595474
A9: 45504 | B9: 2272153
A10: 45535 | B10: 1102882
A11: 45565 | B11: 1427156
A12: 45580 | B12: 1301061
A13: 45596 | B13: 2232987
A14: 45615 | C14: 2682276
A15: 45616 | C15: 330000
A16: 45616 | C16: 470902
A17: 45626 | B17: 4139787
A18: 45628 | C18: 1901130
A19: 45632 | C19: 2238657
A20: 45657 | B20: 5219468
A21: 45673 | C21: 1500000
A22: 45313 | C22: 1000000
A23: 45684 | C23: 1000000
A24: 45684 | C24: 2000000
A25: 45688 | B25: 4466778
A26: 45706 | C26: 2000000 | D26: transfirio
A27: 45712 | C27: 1186246
A28: 45712 | C28: 1000000
A29: 45716 | B29: 3172224
A30: 45737 | C30: 3000000
A31: 45747 | B31: 2274679
A32: 45770 | C32: 2446903
A33: 45777 | B33: 1635512
A34: 45792 | C34: 1712000
A35: 45807 | B35: 1029527
A36: 45818 | C36: 953039
A37: 45838 | B37: 622282
A38: 45852 | C38: 622282
A39: 45869 | B39: 2194097
A40: 45873 | C40: 2000000 | D40: cheque
...

Sheet RUCA
A1: RUCA | D1: volver
A2: FECHA | B2: IMPORTE ADEUDADO | C2: ENTREGAS | D2: FORMA DE PAGO | E2: DETALLE | F2: TOTAL | G2: =SUM(C3:C1048576) - SUM(B3:B1048576) -> -6166094
A4: 41578 | B4: 536722 | E4: RUCA
A5: 45260 | B5: 746625 | E5: RUCA
A6: 45291 | B6: 628630 | E6: RUCA
A7: 45322 | B7: 758154 | E7: RUCA
A8: 45351 | B8: 603806 | E8: RUCA
A9: 45382 | B9: 336528 | E9: RUCA
A10: 45412 | B10: 467947 | E10: RUCA
A11: 45443 | B11: 310532 | E11: RUCA
A12: 45473 | B12: 378777 | E12: RUCA
A13: 45504 | B13: 724996 | E13: RUCA
A16: 45625 | C16: 510361
A17: 45626 | B17: 1183738

Sheet TAGORE
A1: TAGORE | D1: volver
A2: FECHA | B2: IMPORTE ADEUDADO | C2: ENTREGAS | D2: FORMA DE PAGO | E2: DETALLE | F2: TOTAL | G2: =SUM(C3:C1048576) - SUM(B3:B1048576) -> -1431612
A4: 01/1 AL 31/4 | B4: 1293641
A5: 45425 | C5: 1293641 | D5: TRANSF.
A6: 45473 | B6: 164115
A7: 45504 | B7: 646773
B8: 170287
A9: 45512 | C9: 981175
A10: 45535 | B10: 30504
A11: 45565 | B11: 50350
A12: 45596 | B12: 760193
A13: 45626 | B13: 1760454
A14: 45636 | C14: 2601501
A15: 45657 | B15: 944852
A16: 45688 | C16: 944852
A17: 45688 | B17: 1577742
A18: 45716 | B18: 1223828
A19: 45726 | C19: 1577742
A20: 45736 | C20: 1223828
A21: 45747 | B21: 334251
A22: 45777 | B22: 81738
A23: 45807 | B23: 236405
A24: 45839 | C24: 652394
A25: 45869 | B25: 832437
A26: 45881 | C26: 832437
A27: 45900 | B27: 259822
A28: 45930 | B28: 212829
A29: 45961 | B29: 706602
A30: 45981 | C30: 1179253
A31: 45991 | B31: 2473861
A32: 46015 | C32: 1300000
A33: 46020 | C33: 1173861
A34: 46022 | B34: 2905666
A35: 46042 | C35: 2905666
A36: 46053 | B36: 1170902
A37: 46079 | C37: 1170902
A38: 46081 | B38: 1431612

Sheet TOULON
A1: TOULON | D1: volver
A2: FECHA | B2: IMPORTE ADEUDADO | C2: ENTREGAS | D2: FORMA DE PAGO | E2: DETALLE | F2: TOTAL | G2: =SUM(C3:C1048576) - SUM(B3:B1048576) -> -763464
A4: 45443 | B4: 86180
C5: 86180
A6: 45473 | B6: 185913
C7: 115913
A8: 45504 | B8: 491694
A9: 45525 | C9: 150000
A10: 45535 | B10: 169249
A11: 45544 | C11: 200000
A12: 45553 | C12: 380943
A13: 45565 | B13: 155415
A14: 45587 | C14: 155415
A15: 45596 | B15: 328712
A16: 45625 | C16: 328712
A17: 45626 | B17: 288311
A18: 45646 | C18: 200000
A19: 45657 | B19: 281036
A20: 45674 | C20: 168000
A21: 45679 | C21: 201347
A22: 45688 | B22: 463483
A23: 45700 | C23: 200000
A24: 45716 | B24: 751052
A25: 45741 | C25: 500000
A26: 45747 | B26: 431941
A27: 45765 | C27: 300000
A28: 45777 | B28: 184722
A29: 45807 | B29: 104559
A30: 45835 | C30: 3300000 | D30: CHEQUE
A31: 45838 | B31: 118272
A32: 45869 | B32: 694588
A33: 45900 | B33: 290993
A34: 45930 | B34: 389598 | E34: 0
A35: 45961 | B35: 292724
A36: 45991 | B36: 480199
A37: 46022 | B37: 385585
A38: 46041 | C38: 287716
A39: 46053 | B39: 880079
A40: 46073 | C40: 500000
A41: 46081 | C41: 380079
...

Sheet VAIVEN POSADA
A1: VAIVEN POSADA | D1: volver
A2: FECHA | B2: IMPORTE ADEUDADO | C2: ENTREGAS | D2: FORMA DE PAGO | E2: DETALLE | F2: TOTAL | G2: =SUM(C3:C1048576) - SUM(B3:B1048576) -> -1915865
A4: 45443 | B4: 607452
A5: 45455 | C5: 607452
A6: 45473 | B6: 674908
A7: 45488 | C7: 674908
A8: 45504 | B8: 837969
A9: 45516 | C9: 837969
A10: 45535 | B10: 620451
A11: 45553 | C11: 620451
A12: 45565 | B12: 658149
A13: 45579 | C13: 658149
A14: 45596 | B14: 569084
A15: 45608 | C15: 569084
A16: 45625 | B16: 699684
A17: 45635 | C17: 699684
A18: 45657 | B18: 705916
A19: 45671 | C19: 705916
A20: 45688 | B20: 890849
A21: 45701 | C21: 890849
A22: 45716 | B22: 829212
A23: 45742 | C23: 829212 | D23: EFT
A24: 45747 | B24: 772685
A25: 45787 | C25: 772685
A26: 45777 | B26: 588174
C27: 588174
A28: 45807 | B28: 554187
A29: 45838 | B29: 310655
A30: 45869 | B30: 554755
A31: 45871 | C31: 554187
A32: 45897 | C32: 310655
A33: 45900 | B33: 614893
A34: 45924 | C34: 554755
A35: 45930 | B35: 672904
A36: 45948 | C36: 614893
A37: 45961 | B37: 695947
A38: 45987 | C38: 672904
A39: 45991 | B39: 754825
A40: 46011 | C40: 695947
A41: 46022 | B41: 752863
...

Sheet VENETO
A1: VENETO | D1: volver
A2: FECHA | B2: IMPORTE ADEUDADO | C2: ENTREGAS | D2: FORMA DE PAGO | E2: DETALLE | F2: TOTAL | G2: =SUM(C3:C1048576) - SUM(B3:B1048576) -> -498393
A4: 45443 | B4: 237593
A5: 45455 | C5: 237593
A6: 45473 | B6: 905683
A7: 45504 | B7: 1675963
A8: 45509 | C8: 2000000
A9: 45526 | C9: 300000
A10: 45535 | B10: 515067
A11: 45558 | C11: 690000
A12: 45565 | B12: 700802
A13: 45581 | C13: 700000
A14: 45596 | B14: 1510361
A15: 45611 | C15: 1000000
A16: 45625 | C16: 510361
A17: 45626 | B17: 1183738
A18: 45645 | C18: 1291253
A19: 45657 | B19: 1213213
A20: 45673 | C20: 1213213
A21: 45688 | B21: 2857233
A22: 45701 | C22: 2300000
A23: 45709 | C23: 557233
A24: 45716 | B24: 2382565
A25: 45734 | C25: 2382565
A26: 45747 | B26: 1407414
A27: 45749 | C27: 1008000 | D27: efectivo
A28: 45749 | C28: 400000 | D28: transferencia a Jere
A29: 45777 | B29: 1425322
A30: 45801 | C30: 1000000 | D30: efectivo
A31: 45807 | B31: 720651
A32: 45819 | C32: 1000000 | D32: efectivo
A33: 45838 | B33: 653741
A34: 45849 | C34: 800000 | D34: efectivo
A35: 45869 | B35: 1685724
A36: 45881 | C36: 1325000
A37: 45900 | B37: 921348
A38: 45908 | C38: 1000000
A39: 45930 | B39: 900453
A40: 45937 | C40: 1000000
A41: 45961 | B41: 1160273
...

Sheet VILLA PAZ
A1: VILLA PAZ | D1: volver
A2: FECHA | B2: IMPORTE ADEUDADO | C2: ENTREGAS | D2: FORMA DE PAGO | E2: DETALLE | F2: TOTAL | G2: =SUM(C3:C1048576) - SUM(B3:B1048576) -> 0
A4: 45473 | B4: 1054973
A5: 45488 | C5: 1054973
A6: 45504 | B6: 1636590
A7: 45519 | C7: 1636590
A8: 45535 | B8: 1183847
A9: 45551 | C9: 1183847
A10: 45565 | B10: 1440186
A11: 45583 | C11: 1440186
A12: 45596 | B12: 1705233
A13: 45608 | C13: 1705233
A14: 45626 | B14: 1152720
A15: 45636 | C15: 1152720
A16: 45657 | B16: 1622076
A17: 45681 | C17: 1622076
A18: 45688 | B18: 3047925
A19: 45696 | C19: 3047925
A20: 45716 | B20: 2670643
A21: 45734 | C21: 2670643
A22: 45747 | B22: 1482278
A23: 45765 | C23: 1482278
A24: 45777 | B24: 1545313
A25: 45786 | C25: 1545313
A26: 45807 | B26: 1447682
A27: 45813 | C27: 1447682
A28: 45838 | B28: 1361087
A29: 45855 | C29: 1361087
A30: 45869 | B30: 2173510
C31: 2173510
A32: 45900 | B32: 1478821
A33: 45909 | C33: 1478821
A34: 45930 | B34: 1494707
A35: 45941 | C35: 1494707
A36: 45961 | B36: 1423666
A37: 45968 | C37: 1423666
A38: 45991 | B38: 1496037
A39: 46008 | C39: 1496037
A40: 46022 | B40: 1672905
A41: 46031 | C41: 1672905
...

Sheet VILLA PIREN
A1: VILLA PIREN | D1: volver
A2: FECHA | B2: IMPORTE ADEUDADO | C2: ENTREGAS | D2: FORMA DE PAGO | E2: DETALLE | F2: TOTAL | G2: =SUM(C3:C1048576) - SUM(B3:B1048576) -> -6016929
A4: DEUDA ANTERIOR | B4: 590048
C5: 590048 | D5: transf.
A6: 26/7 al12/8 | B6: 526426 | E6: cabañas
A7: 26/7 al12/8 | B7: 533482 | E7: apart
A8: 13/8 al26/8 | B8: 641417 | E8: apart
A9: 13/8 al 26/8 | B9: 418099 | E9: cabañas
A10: 45533 | C10: 1059908 | D10: transf.
A11: 27/8 AL 11/9 | B11: 801908 | E11: APART
A12: 27/8 AL 11/9 | B12: 443216 | E12: cabañas
A13: 45575 | C13: 641417
A14: 12/9 al 9/10 | B14: 1318792 | E14: cabaña
A15: 12/9 al 9/10 | B15: 1352497 | E15: apart
A16: 45584 | C16: 1245124 | D16: transf.
A18: 10/10 al 6/11 | B18: 948304 | E18: cabañas
A19: 10/10 al 6/11 | B19: 1258258 | E19: apart
A20: 45618 | C20: 1352497
A21: 7/11 al 6/12 | B21: 1296569 | E21: cabañas
A22: 7/11 al 6/12 | B22: 1667460 | E22: apart
A23: 45637 | C23: 3525354
A24: 45657 | B24: 888668 | E24: CABAÑAS
A25: 45657 | B25: 1119225
A26: 45657 | C26: 2964029
A27: 45667 | C27: 1119225
A28: 45680 | C28: 1306767
A29: 45707 | B29: 882150 | E29: apart
A30: 45707 | B30: 628858 | E30: cabañas
A31: 45712 | C31: 1511008
A33: 45751 | B33: 721548 | E33: apart
A34: 45751 | B34: 387855 | E34: cabañas
A35: 45791 | B35: 1766971 | E35: apart
A36: 45791 | B36: 1194941 | E36: cabañas
A37: 45800 | C37: 1000000 | D37: ECHEC
A38: 45800 | C38: 1000000 | D38: ECHEC
A39: 45800 | C39: 1000000 | D39: ECHEC
A40: 45800 | C40: 1071315 | D40: ECHEC
A41: 45832 | B41: 1191424 | E41: cabañas
A42: 45832 | B42: 1886996 | E42: apart
A43: 45845 | C43: 500000
...

Sheet VITTO
A1: VITTO | D1: volver
A2: FECHA | B2: IMPORTE ADEUDADO | C2: ENTREGAS | D2: FORMA DE PAGO | E2: DETALLE | F2: TOTAL | G2: =SUM(C3:C1048576) - SUM(B3:B1048576) -> 0
A4: 45504 | B4: 85599
A5: 45519 | C5: 85599
A6: 45535 | B6: 36645
A7: 45551 | C7: 36645
A8: 45565 | B8: 72885
A9: 45583 | C9: 72885
A10: 45596 | B10: 51108
A11: 45602 | C11: 51108
A12: 45626 | B12: 79139
A13: 45636 | C13: 79139
A14: 45657 | B14: 122301
A15: 45315 | C15: 122301
A16: 45688 | B16: 144211
A17: 45696 | C17: 144211
A18: 45716 | B18: 248362
A19: 45734 | C19: 248362
A20: 45747 | B20: 109521
A21: 45777 | B21: 95232
A22: 45756 | C22: 204753
A23: 45807 | B23: 188495
A24: 45813 | C24: 188495
A25: 45838 | B25: 51076
C26: 51076
A27: 45869 | B27: 204487
C28: 204487
A29: 45900 | B29: 223197
A30: 45909 | C30: 223197
A31: 45930 | B31: 57329
A32: 45941 | C32: 57329
A33: 45961 | B33: 138798
A34: 45968 | C34: 138798
A35: 45991 | B35: 80046
A36: 46008 | C36: 80046
A37: 46022 | B37: 195171
A38: 46031 | C38: 195171
A39: 46053 | B39: 293569
A40: 46059 | C40: 293569
A41: 46081 | B41: 331604
...

Sheet WYNWOOD
A1: WYNWOOD | D1: volver
A2: FECHA | B2: IMPORTE ADEUDADO | C2: ENTREGAS | D2: FORMA DE PAGO | E2: DETALLE | F2: TOTAL | G2: =SUM(C3:C1048576) - SUM(B3:B1048576) -> -527000
A4: 45443 | B4: 52258 | E4: winwood
A5: 45473 | B5: 187075 | E5: winwood
A6: 45504 | B6: 287667 | E6: winwood

Sheet Y 111
A1: Y 111 | D1: volver
A2: FECHA | B2: IMPORTE ADEUDADO | C2: ENTREGAS | D2: FORMA DE PAGO | E2: DETALLE | F2: TOTAL | G2: =SUM(C3:C1048576) - SUM(B3:B1048576) -> 0
A4: 45473 | B4: 4198390
A5: 45488 | C5: 4198390
A6: 45504 | B6: 4689338
A7: 45516 | C7: 4689338
A8: 45535 | B8: 3851464
A9: 45548 | C9: 3851464
A10: 45565 | B10: 3959487
A11: 45579 | C11: 3959487
A12: 45596 | B12: 5196001
A13: 45611 | C13: 5196001
A14: 45626 | B14: 4827721
A15: 45638 | C15: 4827721
A16: 45657 | B16: 4266986
A17: 45674 | C17: 4266986
A18: 45688 | B18: 3102424
A19: 45702 | C19: 3102424
A20: 45716 | B20: 4365802
A21: 45730 | C21: 4365802
A22: 45747 | B22: 5476379
A23: 45761 | C23: 5476379
A24: 45777 | B24: 5928398
A25: 45792 | C25: 5928398
A26: 45807 | B26: 6988338
A27: 45824 | C27: 6988338 | D27: cheques
A28: 45838 | B28: 6857542
A29: 45849 | C29: 6857542 | D29: cheques
A30: 45869 | B30: 8251085
A31: 45883 | C31: 8251085 | D31: cheques
A32: 45900 | B32: 8346848
A33: 45911 | C33: 8346848
A34: 45930 | B34: 9067690
A35: 45940 | C35: 8919154.2 | D35: cheques
A36: 45961 | B36: 8064396
A37: 45974 | C37: 8212931.8 | D37: CHEQUES
A38: 45991 | B38: 8817747
A39: 46002 | C39: 8817747 | D39: cheques
A40: 46022 | B40: 8221860
A41: 46037 | C41: 8221860
...

Sheet FLY KITCHEN
A1: RITZ | D1: volver
A2: FECHA | B2: IMPORTE ADEUDADO | C2: ENTREGAS | D2: FORMA DE PAGO | E2: DETALLE | F2: TOTAL | G2: =SUM(C3:C1048576) - SUM(B3:B1048576) -> 0
A3: 45991 | B3: 85874
A4: 46053 | B4: 133653
A5: 46087 | C5: 219527

Sheet TRES PIRCAS
A1: TRES PIRCAS | D1: volver
A2: FECHA | B2: IMPORTE ADEUDADO | C2: ENTREGAS | D2: FORMA DE PAGO | E2: DETALLE | F2: TOTAL | G2: =SUM(C4:C179) - SUM(B3:B179) -> -380420
A3: 45960 | B3: 1380420
A4: 45976 | C4: 1000000

Sheet HENIA
A1: HENIA | D1: volver
A2: FECHA | B2: IMPORTE ADEUDADO | C2: ENTREGAS | D2: FORMA DE PAGO | E2: DETALLE | F2: TOTAL | G2: =SUM(C3:C107) - SUM(B3:B107) -> 0
A3: 45930 | B3: 476000
A4: 45952 | C4: 476000
A5: 45961 | B5: 1587738
A6: 45978 | C6: 1000000
A7: 46009 | C7: 500000
A8: 46022 | B8: 1719081
A9: 46030 | C9: 1250000
A10: 46034 | C10: 1000000
A11: 46053 | B11: 1443181
A12: 46055 | C12: 1000000
A13: 46081 | B13: 1665191
A14: 46082 | C14: 1000000
A15: 46100 | C15: 665191
